Workbook

Sheet Figure 2
A2: Figure 2
A4: Panel | B4: Clone time point | C4: Clone size | F4: No. organoids | G4: Statistical test | R4: Panel | S4: Clone time point | T4: Number clones | X4: Percent of all clones
C5: Mean | D5: SEM | E5: No. clones | T5: Prolif | U5: Asym | V5: Small | W5: total | X5: Prolif | Y5: SEMp | Z5: Asym | AA5: SEMp | AB5: Small | AC5: SEMp
A6: g | B6: D8 | C6: 25.97 | D6: 2.809 | E6: 109 | F6: 100 | I6: P value | J6: K-W statistic | K6: Mean rank 1 | L6: Mean rank 2 | M6: Mean rank diff. | N6: n1 | O6: n2 | P6: Z | R6: K | S6: D8 | T6: 53 | U6: 32 | V6: 24 | W6: =T6+U6+V6 -> 109 | X6: =T6/W6*100 -> 48.623853 | Y6: 4.7873 | Z6: =U6/W6*100 -> 29.357798 | AA6: 4.3619 | AB6: =V6/W6*100 -> 22.018349 | AC6: 3.9689
A7: All clones | B7: D9 | C7: 23.35 | D7: 4.427 | E7: 46 | F7: 49 | G7: Kruskal-Wallis test | H7: D8-D15 | I7: 0.0001 | J7: 86.91 | S7: D9 | T7: 20 | U7: 15 | V7: 11 | W7: =T7+U7+V7 -> 46 | X7: =T7/W7*100 -> 43.478261 | Y7: 7.3091 | Z7: =U7/W7*100 -> 32.608696 | AA7: 6.9118 | AB7: 22.916667 | AC7: 6.2892
B8: D10 | C8: 23.2 | D8: 2.386 | E8: 93 | F8: 165 | G8: Dunn's multiple comparisons | H8: D8 v D9 | I8: >0.9999 | K8: 284.3 | L8: 267.1 | M8: 17.48 | N8: 109 | O8: 46 | P8: 0.7383 | S8: D10 | T8: 46 | U8: 31 | V8: 16 | W8: =T8+U8+V8 -> 93 | X8: =T8/W8*100 -> 49.462366 | Y8: 5.1845 | Z8: =U8/W8*100 -> 33.333333 | AA8: 4.8882 | AB8: 16.161616 | AC8: 3.9136
B9: D11 | C9: 14.52 | D9: 2.391 | E9: 50 | F9: 67 | H9: D9 v D10 | I9: >0.9999 | K9: 266.3 | L9: 290.8 | M9: -23.74 | N9: 46 | O9: 93 | P9: 0.9775 | S9: D11 | T9: 18 | U9: 14 | V9: 18 | W9: =T9+U9+V9 -> 50 | X9: =T9/W9*100 -> 36 | Y9: 6.7882 | Z9: =U9/W9*100 -> 28 | AA9: 6.3498 | AB9: 36 | AC9: 6.7882
B10: D12 | C10: 10.74 | D10: 1.446 | E10: 61 | F10: 50 | H10: D10 v D11 | I10: 0.0092 | K10: 290.5 | L10: 216 | M10: 74.85 | N10: 93 | O10: 50 | P10: 3.169 | S10: D12 | T10: 17 | U10: 17 | V10: 27 | W10: =T10+U10+V10 -> 61 | X10: =T10/W10*100 -> 27.868852 | Y10: 5.7406 | Z10: =U10/W10*100 -> 27.868852 | AA10: 5.7406 | AB10: 44.262295 | AC10: 6.3596
B11: D13 | C11: 7.368 | D11: 0.7903 | E11: 68 | F11: 133 | H11: D11 v D12 | I11: >0.9999 | K11: 208.4 | L11: 200.3 | M11: 15.66 | N11: 50 | O11: 61 | P11: 0.6094 | S11: D13 | T11: 13 | U11: 20 | V11: 35 | W11: =T11+U11+V11 -> 68 | X11: =T11/W11*100 -> 19.117647 | Y11: 4.7686 | Z11: =U11/W11*100 -> 29.411765 | AA11: 5.5255 | AB11: 50.724638 | AC11: 6.0608
B12: D15 | C12: 4.65 | D12: 0.469 | E12: 40 | F12: 63 | H12: D12 v D13 | I12: 0.7408 | K12: 197 | L12: 163.7 | M12: 36.59 | N12: 61 | O12: 68 | P12: 1.54 | S12: D15 | T12: 0 | U12: 10 | V12: 30 | W12: =T12+U12+V12 -> 40 | X12: =T12/W12*100 -> 0 | Y12: 0 | Z12: =U12/W12*100 -> 25 | AA12: 6.8465 | AB12: 73.170732 | AC12: 6.8465
H13: D13 v D15 | I13: 0.5879 | K13: 172.7 | L13: 119.3 | M13: 44.42 | N13: 68 | O13: 40 | P13: 1.655
A14: h | B14: D8 | C14: 44.17 | D14: 4.495 | E14: 53 | F14: 100
A15: Prolif | B15: D9 | C15: 44 | D15: 8.053 | E15: 20 | F15: 49 | G15: Kruskal-Wallis test | H15: D8-D13 | I15: 0.0004 | J15: 24.42
B16: D10 | C16: 37.07 | D16: 3.692 | E16: 46 | F16: 165 | G16: Dunn's multiple comparisons | H16: D8 v D9 | I16: >0.9999 | K16: 95.92 | L16: 94.8 | M16: 1.125 | N16: 53 | O16: 20 | P16: 0.08812
B17: D11 | C17: 31.28 | D17: 4.354 | E17: 18 | F17: 67 | H17: D9 v D10 | I17: >0.9999 | K17: 94.8 | L17: 90.78 | M17: 4.017 | N17: 20 | O17: 46 | P17: 0.3085
B18: D12 | C18: 24.35 | D18: 3.21 | E18: 17 | F18: 50 | H18: D10 v D11 | I18: >0.9999 | K18: 90.78 | L18: 82.03 | M18: 8.755 | N18: 46 | O18: 18 | P18: 0.6476
B19: D13 | C19: 14.46 | D19: 2.096 | E19: 13 | F19: 133 | H19: D11 v D12 | I19: >0.9999 | K19: 82.03 | L19: 66.62 | M19: 15.41 | N19: 18 | O19: 17 | P19: 0.9371
H20: D12 v D13 | I20: 0.3059 | K20: 66.62 | L20: 33.08 | M20: 33.54 | N20: 17 | O20: 13 | P20: 1.872
A22: I | B22: D8 | C22: 12.59 | D22: 1.371 | E22: 32 | F22: 100
A23: Asym. | B23: D9 | C23: 10.33 | D23: 1.588 | E23: 15 | F23: 49 | G23: Kruskal-Wallis test | H23: D8-D15 | I23: 0.3433 | J23: 6.763
B24: D10 | C24: 12.77 | D24: 1.501 | E24: 31 | F24: 165 | G24: Dunn's multiple comparisons | H24: D8 v D9 | I24: >0.9999 | K24: 79.41 | L24: 63.97 | M24: 15.44 | N24: 32 | O24: 15 | P24: 1.232
B25: D11 | C25: 8.071 | D25: 0.6668 | E25: 14 | F25: 67 | H25: D9 v D10 | I25: >0.9999 | K25: 63.97 | L25: 76.56 | M25: -12.6 | N25: 15 | O25: 31 | P25: 1
B26: D12 | C26: 8.647 | D26: 0.7809 | E26: 17 | F26: 50 | H26: D10 v D11 | I26: 0.5222 | K26: 76.56 | L26: 54.5 | M26: 22.06 | N26: 31 | O26: 14 | P26: 1.711
B27: D13 | C27: 10.65 | D27: 1.206 | E27: 20 | F27: 133 | H27: D11 v D12 | I27: >0.9999 | K27: 54.5 | L27: 59.18 | M27: -4.676 | N27: 14 | O27: 17 | P27: 0.3236
B28: D15 | C28: 8.7 | D28: 0.9074 | E28: 10 | F28: 63 | H28: D12 v D13 | I28: >0.9999 | K28: 59.18 | L28: 73.15 | M28: -13.97 | N28: 17 | O28: 20 | P28: 1.058
H29: D13 v D15 | I29: >0.9999 | K29: 73.15 | L29: 62.4 | M29: 10.75 | N29: 20 | O29: 10 | P29: 0.6932
A30: J | B30: D8 | C30: 3.524 | D30: 0.3057 | E30: 24 | F30: 100
A31: Small | B31: D9 | C31: 3.545 | D31: 0.3659 | E31: 11 | F31: 49 | G31: Kruskal-Wallis test | H31: D8-D15 | I31: 0.0966 | J31: 10.74
B32: D10 | C32: 3.563 | D32: 0.2734 | E32: 16 | F32: 165 | G32: Dunn's multiple comparisons | H32: D8 v D9 | I32: >0.9999 | K32: 91.1 | L32: 92.36 | M32: -1.259 | N32: 24 | O32: 11 | P32: 0.07701
B33: D11 | C33: 2.778 | D33: 0.1906 | E33: 18 | F33: 67 | H33: D9 v D10 | I33: >0.9999 | K33: 92.36 | L33: 94.56 | M33: -2.199 | N33: 11 | O33: 16 | P33: 0.125
B34: D12 | C34: 3.481 | D34: 0.2288 | E34: 27 | F34: 50 | H34: D10 v D11 | I34: 0.2765 | K34: 94.56 | L34: 63.78 | M34: 30.78 | N34: 16 | O34: 18 | P34: 1.995
B35: D13 | C35: 2.857 | D35: 0.1486 | E35: 35 | F35: 133 | H35: D11 v D12 | I35: 0.3344 | K35: 63.78 | L35: 89.93 | M35: -26.15 | N35: 18 | O35: 27 | P35: 1.913
B36: D15 | C36: 3.3 | D36: 0.2404 | E36: 30 | F36: 63 | H36: D12 v D13 | I36: 0.2497 | K36: 89.93 | L36: 66.49 | M36: 23.44 | N36: 27 | O36: 35 | P36: 2.037
H37: D13 v D15 | I37: >0.9999 | K37: 66.49 | L37: 80.75 | M37: -14.26 | N37: 35 | O37: 30 | P37: 1.276

Sheet Figure 3
A2: Figure 3
A4: Panel | B4: Clone type | C4: No. clones containing: | E4: No. clones | F4: Precent all clones | G4: Standard Error of Proportion | I4: Standard Error of Proportion
C5: Ctip2 only | D5: Satb2 only | E5: total | F5: Ctip2 only | H5: Satb2 only
A6: k (left, D8) | B6: Prolif. | C6: 8 | D6: 1 | E6: 37 | F6: =C6/E6*100 -> 21.621622 | G6: 6.77 | H6: =D6/E6*100 -> 2.7027027 | I6: 2.67
B7: Asym. | C7: 6 | D7: 1 | E7: 28 | F7: =C7/E7*100 -> 21.428571 | G7: 7.75 | H7: =D7/E7*100 -> 3.5714286 | I7: 3.51 | J7: Note: clone data in this figure is partially included in the n and statistics of Figure 2
B8: Small | C8: 12 | D8: 3 | E8: 22 | F8: =C8/E8*100 -> 54.545455 | G8: 10.21 | H8: =D8/E8*100 -> 13.636364 | I8: 6.75
A9: k (right, D13) | B9: Prolif. | C9: 2 | D9: 3 | E9: 24 | F9: =C9/E9*100 -> 8.3333333 | G9: 5.6417 | H9: =D9/E9*100 -> 12.5 | I9: 6.7508
B10: Asym. | C10: 8 | D10: 3 | E10: 31 | F10: =C10/E10*100 -> 25.806452 | G10: 7.859 | H10: =D10/E10*100 -> 9.6774194 | I10: 5.31
B11: Small | C11: 7 | D11: 2 | E11: 23 | F11: =C11/E11*100 -> 30.434783 | G11: 9.5944 | H11: =D11/E11*100 -> 8.6956522 | I11: 5.8753
A13: Statistical analysis and raw data see Extended Data Figure 21
A16: Panel | B16: Condition | C16: No. clones | D16: No. clones | E16: Percent | F16: Standard Error of Proportion
C17: lineage restricted | D17: total | E17: restricted
A18: l | B18: Organoid D8 | C18: 31 | D18: 87 | E18: =C18/D18*100 -> 35.632184 | F18: 5.13
B19: Organoid D13 | C19: 25 | D19: 78 | E19: =C19/D19*100 -> 32.051282 | F19: 5.284
B20: *In vivo | C20: 11 | D20: 386 | E20: 2.8497 | F20: 0.8469
A22: *In vivo data sources:
A23: Publication | B23: Time point | C23: No. clones | D23: No. clones | E23: Method of analysis
C24: lineage restricted | D24: total
A25: Gao et al. (Fig. 4C) | B25: E10-12 | C25: 2 | D25: 263 | E25: laminar position based on DAPI
A27: Gao et al. (Fig. S5) | B27: E10-12 | C27: 0 | D27: 17 | E27: Immunostaining layer specific markers
A29: Llorca et al., (Fig 3D) | B29: E12 | C29: 9 | D29: 106 | E29: laminar position based on DAPI

Sheet Extended Data
A2: Ext. Data Fig. 1
A3: Panels g & p | B3: Cell Line | C3: # Cells w/Normal Karyotype | D3: # Cells w/Chr. 8 Trisomy | E3: # Cells w/Chr. 11 Trisomy
B4: A1 | C4: 18 | D4: 0 | E4: 2
B5: A2 | C5: 14 | D5: 3 | E5: 3
B6: B1 | C6: 20 | D6: 0 | E6: 0
B7: B2 | C7: 20 | D7: 5 | E7: 0
A10: Ext. Data Fig. 9
A11: Panels i-j | B11: Cell Line | C11: # Cells w/41-42 Chromosomes | D11: # Cells w/40 Chromosomes | E11: # Cells w/37-39 Chromosomes | F11: Mean Chr. Number
B12: A7 | C12: 5 | D12: 16 | E12: 5 | F12: 39.96
B13: F27 | C13: 3 | D13: 15 | E13: 5 | F13: 39.78
A16: Ext. Data Fig. 10
A17: Panel l | C17: Number of cells
C18: MADM+PAX6+ | D18: MADM+TBR2+ | E18: MADM+CTIP2+ | F18: MADM+SATB2+
B19: D10 | C19: 8 | D19: 19 | E19: 9 | F19: 0
B20: D13 | C20: 906 | D20: 573 | E20: 297 | F20: 17
B21: D16 | C21: 1677 | D21: 133 | E21: 1510 | F21: 753
B22: D20 | C22: 179 | D22: 140 | E22: 953 | F22: 889
A24: Fisher's Exact Test
B25: pvalue | C25: padj (Bonferroni)
A26: D10-D13 | B26: 0.0066421947 | C26: 0.019926584
A27: D13-D16 | B27: 8.0643184e-290 | C27: 2.4192955e-289
A28: D16-D20 | B28: 1.5357945e-181 | C28: 4.6073835e-181
A30: All 2-way comparisons, Fisher's Exact Test
A31: type | B31: comparison | C31: pvalue | D31: padj (Bonferroni)
A32: SATB2 | B32: D13_vs_D20 | C32: 1.88282e-248 | D32: 4.5187681e-247
A33: PAX6 | B33: D13_vs_D20 | C33: 3.9305261e-203 | D33: 9.4332626e-202
A34: TBR2 | B34: D13_vs_D16 | C34: 2.8525196e-196 | D34: 6.8460471e-195
A35: PAX6 | B35: D16_vs_D20 | C35: 5.4543558e-184 | D35: 1.3090454e-182
A36: SATB2 | B36: D13_vs_D16 | C36: 1.8896557e-103 | D36: 4.5351737e-102
A37: TBR2 | B37: D13_vs_D20 | C37: 3.4644025e-99 | D37: 8.3145661e-98
A38: SATB2 | B38: D16_vs_D20 | C38: 1.4620033e-80 | D38: 3.508808e-79
A39: CTIP2 | B39: D13_vs_D20 | C39: 7.5433651e-80 | D39: 1.8104076e-78
A40: CTIP2 | B40: D13_vs_D16 | C40: 2.9783731e-59 | D40: 7.1480954e-58
A41: TBR2 | B41: D10_vs_D16 | C41: 1.0112268e-18 | D41: 2.4269444e-17
A42: TBR2 | B42: D10_vs_D20 | C42: 2.2258609e-13 | D42: 5.342066e-12
A43: PAX6 | B43: D13_vs_D16 | C43: 3.3902301e-11 | D43: 8.1365523e-10
... A55: SATB2 | B55: D10_vs_D13 | C55: 1 | D55: 1
A58: Ext. Data Fig. 11
A60: Panel | B60: Time point D10 | C60: % CASP+MADM+/MADM+ cells | D60: SEM | E60: No. organoids
A61: g | B61: Batch 1 | C61: 0.02854375 | D61: 0.86 | E61: 16
...

Sheet Data by Line
B3: Cell Line | C3: Clone time point | D3: Clone size | G3: Statistical test
D4: Mean | E4: SEM | F4: No. clones
B5: 2A | C5: D8 | D5: 24.04 | E5: 4.265 | F5: 45 | I5: P value | J5: K-W statistic | K5: Mean rank 1 | L5: Mean rank 2 | M5: Mean rank diff. | N5: n1 | O5: n2 | P5: Z
B6: All clones | C6: D9 | D6: 15.61 | E6: 3.701 | F6: 18 | G6: Kruskal-Wallis test | H6: D8-D15 | I6: <0.0001 | J6: 29.12
C7: D10 | D7: 21.74 | E7: 3.693 | F7: 27 | G7: Dunn's multiple comparisons | H7: D8 v D9 | I7: 0.5874 | K7: 85.34 | L7: 67.92 | M7: 17.43 | N7: 45 | O7: 18 | P7: 1.565
C8: D11 | D8: 11.82 | E8: 3.373 | F8: 22 | H8: D9 v D10 | I8: 0.8302 | K8: 67.92 | L8: 84.74 | M8: -16.82 | N8: 18 | O8: 27 | P8: 1.385
C9: D12 | D9: - | E9: - | F9: 0 | H9: D10 v D11 | I9: 0.0538 | K9: 84.74 | L9: 55.5 | M9: 29.24 | N9: 27 | O9: 22 | P9: 2.55
C10: D13 | D10: 7.733 | E10: 2.214 | F10: 15 | H10: D11 v D12 | I10: - | K10: - | L10: - | M10: - | N10: - | O10: - | P10: -
C11: D15 | D11: 4.636 | E11: 0.766 | F11: 11 | H11: D12 v D13 | I11: - | K11: - | L11: - | M11: - | N11: - | O11: - | P11: -
H12: D13 v D15 | I12: >0.9999 | K12: 43.27 | L12: 33.64 | M12: 9.63 | N12: 15 | O12: 11 | P12: 0.6077
B13: 5C | C13: D8 | D13: 26.42 | E13: 4.746 | F13: 38 | I13: P value | J13: K-W statistic | K13: Mean rank 1 | L13: Mean rank 2 | M13: Mean rank diff. | N13: n1 | O13: n2 | P13: Z
B14: All clones | C14: D9 | D14: 28.32 | E14: 6.766 | F14: 28 | G14: Kruskal-Wallis test | H14: D8-D15 | I14: <0.0001 | J14: 35.08
C15: D10 | D15: 23.09 | E15: 4.255 | F15: 34 | G15: Dunn's multiple comparisons | H15: D8 v D9 | I15: >0.9999 | K15: 128.9 | L15: 139.7 | M15: -10.82 | N15: 38 | O15: 28 | P15: 0.6843
C16: D11 | D16: 16.61 | E16: 3.347 | F16: 28 | H16: D9 v D10 | I16: >0.9999 | K16: 139.7 | L16: 137.4 | M16: 2.273 | N16: 28 | O16: 34 | P16: 0.1403
C17: D12 | D17: 10.28 | E17: 2.174 | F17: 32 | H17: D10 v D11 | I17: 0.9176 | K17: 137.4 | L17: 114.3 | M17: 23.16 | N17: 34 | O17: 28 | P17: 1.429
C18: D13 | D18: 7.205 | E18: 1.023 | F18: 39 | H18: D11 v D12 | I18: >0.9999 | K18: 114.3 | L18: 93.95 | M18: 20.33 | N18: 28 | O18: 32 | P18: 1.238
C19: D15 | D19: 5.048 | E19: 0.7699 | F19: 21 | H19: D12 v D13 | I19: >0.9999 | K19: 93.95 | L19: 82.62 | M19: 11.34 | N19: 32 | O19: 39 | P19: 0.7487
H20: D13 v D15 | I20: >0.9999 | K20: 82.62 | L20: 66.6 | M20: 16.02 | N20: 39 | O20: 21 | P20: 0.9323
B21: 3A | C21: D8 | D21: 28.65 | E21: 6.177 | F21: 26 | I21: P value | J21: K-W statistic | K21: Mean rank 1 | L21: Mean rank 2 | M21: Mean rank diff. | N21: n1 | O21: n2 | P21: Z
B22: All clones | C22: D9 | D22: - | E22: - | F22: 0 | G22: Kruskal-Wallis test | H22: D8-D15 | I22: <0.0001 | J22: 24.32
C23: D10 | D23: 24.56 | E23: 4.342 | F23: 32 | G23: Dunn's multiple comparisons | H23: D8 v D9 | I23: - | K23: - | L23: - | M23: - | N23: - | O23: - | P23: -
C24: D11 | D24: - | E24: - | F24: 0 | H24: D9 v D10 | I24: - | K24: - | L24: - | M24: - | N24: - | O24: - | P24: -
C25: D12 | D25: 11.24 | E25: 1.906 | F25: 29 | H25: D10 v D11 | I25: - | K25: - | L25: - | M25: - | N25: - | O25: - | P25: -
C26: D13 | D26: 7.429 | E26: 1.199 | F26: 14 | H26: D11 v D12 | I26: - | K26: - | L26: - | M26: - | N26: - | O26: - | P26: -
C27: D15 | D27: 3.625 | E27: 0.565 | F27: 8 | H27: D12 v D13 | I27: 0.8647 | K27: 47.67 | L27: 39.61 | M27: 8.065 | N27: 29 | O27: 14 | P27: 0.7852
H28: D13 v D15 | I28: 0.2743 | K28: 39.61 | L28: 18.81 | M28: 20.79 | N28: 14 | O28: 8 | P28: 1.486

Sheet Figure 4
A2: Figure 4
A4: Panel | B4: Clone type | C4: Mean | D4: Median | E4: # cells
A6: g | B6: Asym. | C6: 56.2 | D6: 58.8 | E6: 109
B7: Small | C7: 58.2 | D7: 58.9 | E7: 86
A8: h | B8: Translaminar | C8: 58.226493 | D8: 58.8647 | E8: 46
B9: DL restr | C9: 58.371607 | D9: 59.271547 | E9: 26
B10: UL restr | C10: 57.712029 | D10: 58.61396 | E10: 14
A12: (g) Welch Two Sample t-test
A14: t = -2.8704, df = 188.93, p-value = 0.004567
A15: alternative hypothesis: true difference in means is not equal to 0
A16: 95 percent confidence interval:
A17: -3.3688052 | B17: -0.6245023
A18: sample estimates:
A19: mean of x | B19: mean of y
A20: 56.18996 | B20: 58.18661
A22: (h) ANOVA
A23: Df | B23: Sum Sq | C23: Mean Sq | D23: F value | E23: Pr(>F)
A24: 2 | B24: 4.1161738 | C24: 2.0580869 | D24: 0.13180878 | E24: 0.87669168 | F24: Clone Type
A25: 83 | B25: 1295.9775 | C25: 15.614186 | F25: Residuals
A27: (h) Tukey Honest Significant Differences
A28: diff | B28: lwr | C28: upr | D28: p adj
A29: -0.14511368 | B29: -2.4588676 | C29: 2.1686402 | D29: 0.98772723 | E29: Translaminar : DL restr
A30: -0.65957813 | B30: -3.7856273 | C30: 2.466471 | D30: 0.86981418 | E30: UL restr : DL restr
A31: -0.51446445 | B31: -3.3928515 | C31: 2.3639226 | D31: 0.90470349 | E31: UL restr : Translaminar

Sheet cortical layer markers
A1: Upper layer markers | G1: Deep layer markers
A2: gene | B2: Organoid foldChange | C2: Organoid padj | D2: Reference foldChange | E2: Reference padj | G2: gene | H2: Organoid foldChange | I2: Organoid padj | J2: Reference foldChange | K2: Reference padj
A3: Tec | B3: 0.91919449 | C3: 0.0052810172 | D3: 4.7911747 | E3: 1.1227679e-54 | G3: Ngfr | H3: -1.8857959 | I3: 5.6290746e-109 | J3: -7.2691216 | K3: 7.6648389e-198
A4: Kcnj2 | B4: 2.721892 | C4: 3.6175122e-58 | D4: 4.1130124 | E4: 2.3277182e-26 | G4: Lhx9 | H4: -2.5548112 | I4: 8.7533309e-45 | J4: -6.8625536 | K4: 4.370307e-102
A5: Dclk3 | B5: 2.1144842 | C5: 8.5520427e-167 | D5: 4.0812527 | E5: 5.7836065e-31 | G5: Zfp521 | H5: -3.0553274 | I5: 1.6632329e-230 | J5: -6.104145 | K5: 1.2836752e-222
A6: Inhba | B6: 0.62036398 | C6: 7.4561704e-06 | D6: 4.0345689 | E6: 0 | G6: St18 | H6: -2.3883274 | I6: 3.6195454e-208 | J6: -5.5382215 | K6: 7.8016292e-129
A7: Frem2 | B7: 1.5737897 | C7: 9.272403e-27 | D7: 3.8724141 | E7: 1.7011224e-65 | G7: Hs3st4 | H7: -3.8020039 | I7: 3.0657491e-203 | J7: -5.3664612 | K7: 0
A8: Fam19a2 | B8: 1.4880889 | C8: 0 | D8: 3.8330829 | E8: 0 | G8: Nxph3 | H8: -3.2343603 | I8: 1.830613e-234 | J8: -5.2783174 | K8: 0
A9: Cux2 | B9: 1.3871422 | C9: 0 | D9: 3.7768215 | E9: 0 | G9: Crym | H9: -0.69800877 | I9: 9.8856338e-18 | J9: -5.244823 | K9: 0
A10: Cldn1 | B10: 0.98827287 | C10: 0.0047674076 | D10: 3.7089907 | E10: 8.7273494e-27 | G10: Bcl11b | H10: -0.24541014 | I10: 6.8200982e-53 | J10: -5.20284 | K10: 0
A11: Grm2 | B11: 0.52533057 | C11: 2.2515396e-27 | D11: 3.5763456 | E11: 5.5932459e-170 | G11: Nhlh1 | H11: -3.881344 | I11: 0 | J11: -4.8934001 | K11: 4.5533143e-35
A12: Kif26b | B12: 0.59041741 | C12: 1.6973066e-12 | D12: 3.5651508 | E12: 0 | G12: Tle4 | H12: -2.1753117 | I12: 0 | J12: -4.8498462 | K12: 0
A13: Tshr | B13: 1.2807455 | C13: 2.1759122e-28 | D13: 3.5190436 | E13: 3.9391189e-14 | G13: Dmrt3 | H13: -2.8797863 | I13: 3.7316179e-113 | J13: -4.8094494 | K13: 7.0869477e-41
A14: Klhl4 | B14: 2.692664 | C14: 3.5477175e-23 | D14: 3.44583 | E14: 1.0661843e-63 | G14: Nxph4 | H14: -3.4264708 | I14: 4.473861e-274 | J14: -4.7171413 | K14: 0
... A102: Fam84a | B102: 1.1883199 | C102: 1.1232819e-182 | D102: 1.5690583 | E102: 1.6448298e-157 | G102: Tcerg1l | H102: -1.4378183 | I102: 6.3637521e-09 | J102: -2.0397236 | K102: 2.5243657e-51
